
[2025-04-11 16:52:22,321: INFO: main: >>>>>> stage Data Ingestion Stage started <<<<<<]
[2025-04-11 16:52:22,322: INFO: common: yaml file: config/config.yaml loaded successfully]
[2025-04-11 16:52:22,322: INFO: common: yaml file: params.yaml loaded successfully]
[2025-04-11 16:52:22,322: INFO: common: yaml file: schema.yaml loaded successfully]
[2025-04-11 16:52:22,322: INFO: common: created directory at: artifacts]
[2025-04-11 16:52:22,322: INFO: common: created directory at: artifacts/data_ingestion]
[2025-04-11 16:52:23,288: INFO: data_ingestion: artifacts/data_ingestion/data.zip download! with following info: 
Connection: close
Content-Length: 23329
Cache-Control: max-age=300
Content-Security-Policy: default-src 'none'; style-src 'unsafe-inline'; sandbox
Content-Type: application/zip
ETag: "c69888a4ae59bc5a893392785a938ccd4937981c06ba8a9d6a21aa52b4ab5b6e"
Strict-Transport-Security: max-age=31536000
X-Content-Type-Options: nosniff
X-Frame-Options: deny
X-XSS-Protection: 1; mode=block
X-GitHub-Request-Id: 5AB0:30492A:1E0D42A:1F3982C:67F8FB6E
Accept-Ranges: bytes
Date: Fri, 11 Apr 2025 11:22:23 GMT
Via: 1.1 varnish
X-Served-By: cache-bom4747-BOM
X-Cache: MISS
X-Cache-Hits: 0
X-Timer: S1744370543.967009,VS0,VE363
Vary: Authorization,Accept-Encoding,Origin
Access-Control-Allow-Origin: *
Cross-Origin-Resource-Policy: cross-origin
X-Fastly-Request-ID: 2d437ea3b199e954f2e49527d2162aa0404c67ac
Expires: Fri, 11 Apr 2025 11:27:23 GMT
Source-Age: 0

]
[2025-04-11 16:52:23,290: INFO: main: >>>>>> stage Data Ingestion Stage completed <<<<<<

x==========x]
[2025-04-11 16:53:12,263: INFO: main: >>>>>> stage Data Ingestion Stage started <<<<<<]
[2025-04-11 16:53:12,263: INFO: common: yaml file: config/config.yaml loaded successfully]
[2025-04-11 16:53:12,263: INFO: common: yaml file: params.yaml loaded successfully]
[2025-04-11 16:53:12,263: INFO: common: yaml file: schema.yaml loaded successfully]
[2025-04-11 16:53:12,264: ERROR: main: yaml file is empty]
Traceback (most recent call last):
  File "/Users/azizkanch/mlops_learn/MLops-Aziz/src/mlProject/utils/common.py", line 30, in read_yaml
    return ConfigBox(content)
           ^^^^^^^^^^^^^^^^^^
  File "/Users/azizkanch/mlops_learn/MLops-Aziz/mlops/lib/python3.12/site-packages/box/box.py", line 259, in __init__
    raise BoxValueError("First argument must be mapping or iterable")
box.exceptions.BoxValueError: First argument must be mapping or iterable

During handling of the above exception, another exception occurred:

Traceback (most recent call last):
  File "/Users/azizkanch/mlops_learn/MLops-Aziz/main.py", line 8, in <module>
    obj.main()
  File "/Users/azizkanch/mlops_learn/MLops-Aziz/src/mlProject/pipeline/stage_01_ingestion.py", line 11, in main
    config = ConfigurationManager()
             ^^^^^^^^^^^^^^^^^^^^^^
  File "/Users/azizkanch/mlops_learn/MLops-Aziz/src/mlProject/config/configuration.py", line 14, in __init__
    self.schema = read_yaml(schema_filepath)
                  ^^^^^^^^^^^^^^^^^^^^^^^^^^
  File "/Users/azizkanch/mlops_learn/MLops-Aziz/mlops/lib/python3.12/site-packages/ensure/main.py", line 872, in __call__
    return_val = self.f(*args, **kwargs)
                 ^^^^^^^^^^^^^^^^^^^^^^^
  File "/Users/azizkanch/mlops_learn/MLops-Aziz/src/mlProject/utils/common.py", line 32, in read_yaml
    raise ValueError("yaml file is empty")
ValueError: yaml file is empty
[2025-04-11 16:55:19,806: INFO: main: >>>>>> stage Data Ingestion Stage started <<<<<<]
[2025-04-11 16:55:19,806: INFO: common: yaml file: config/config.yaml loaded successfully]
[2025-04-11 16:55:19,807: INFO: common: created directory at: artifacts]
[2025-04-11 16:55:19,807: INFO: common: created directory at: artifacts/data_ingestion]
[2025-04-11 16:55:20,388: INFO: data_ingestion: artifacts/data_ingestion/data.zip download! with following info: 
Connection: close
Content-Length: 23329
Cache-Control: max-age=300
Content-Security-Policy: default-src 'none'; style-src 'unsafe-inline'; sandbox
Content-Type: application/zip
ETag: "c69888a4ae59bc5a893392785a938ccd4937981c06ba8a9d6a21aa52b4ab5b6e"
Strict-Transport-Security: max-age=31536000
X-Content-Type-Options: nosniff
X-Frame-Options: deny
X-XSS-Protection: 1; mode=block
X-GitHub-Request-Id: 5AB0:30492A:1E0D42A:1F3982C:67F8FB6E
Accept-Ranges: bytes
Date: Fri, 11 Apr 2025 11:25:20 GMT
Via: 1.1 varnish
X-Served-By: cache-bom4733-BOM
X-Cache: HIT
X-Cache-Hits: 0
X-Timer: S1744370720.430930,VS0,VE1
Vary: Authorization,Accept-Encoding,Origin
Access-Control-Allow-Origin: *
Cross-Origin-Resource-Policy: cross-origin
X-Fastly-Request-ID: 1e82780dae5d721fdaf6e3bf3064848d5a08f2bb
Expires: Fri, 11 Apr 2025 11:30:20 GMT
Source-Age: 177

]
[2025-04-11 16:55:20,390: INFO: main: >>>>>> stage Data Ingestion Stage completed <<<<<<

x==========x]
[2025-04-11 17:20:04,262: INFO: main: >>>>>> stage Data Validation Stage started <<<<<<]
[2025-04-11 17:20:04,262: INFO: common: yaml file: config/config.yaml loaded successfully]
[2025-04-11 17:20:04,262: INFO: common: yaml file: params.yaml loaded successfully]
[2025-04-11 17:20:04,263: INFO: common: yaml file: schema.yaml loaded successfully]
[2025-04-11 17:20:04,263: INFO: common: created directory at: artifacts]
[2025-04-11 17:20:04,263: ERROR: main: "'ConfigBox' object has no attribute 'columns'"]
Traceback (most recent call last):
  File "/Users/azizkanch/mlops_learn/MLops-Aziz/mlops/lib/python3.12/site-packages/box/box.py", line 503, in __getitem__
    return super().__getitem__(item)
           ^^^^^^^^^^^^^^^^^^^^^^^^^
KeyError: 'COLUMNS'

The above exception was the direct cause of the following exception:

Traceback (most recent call last):
  File "/Users/azizkanch/mlops_learn/MLops-Aziz/mlops/lib/python3.12/site-packages/box/box.py", line 536, in __getattr__
    value = self.__getitem__(item, _ignore_default=True)
            ^^^^^^^^^^^^^^^^^^^^^^^^^^^^^^^^^^^^^^^^^^^^
  File "/Users/azizkanch/mlops_learn/MLops-Aziz/mlops/lib/python3.12/site-packages/box/box.py", line 524, in __getitem__
    raise BoxKeyError(str(err)) from _exception_cause(err)
box.exceptions.BoxKeyError: "'COLUMNS'"

During handling of the above exception, another exception occurred:

Traceback (most recent call last):
  File "/Users/azizkanch/mlops_learn/MLops-Aziz/mlops/lib/python3.12/site-packages/box/box.py", line 538, in __getattr__
    value = object.__getattribute__(self, item)
            ^^^^^^^^^^^^^^^^^^^^^^^^^^^^^^^^^^^
AttributeError: 'ConfigBox' object has no attribute 'COLUMNS'

The above exception was the direct cause of the following exception:

Traceback (most recent call last):
  File "/Users/azizkanch/mlops_learn/MLops-Aziz/mlops/lib/python3.12/site-packages/box/config_box.py", line 28, in __getattr__
    return super().__getattr__(item)
           ^^^^^^^^^^^^^^^^^^^^^^^^^
  File "/Users/azizkanch/mlops_learn/MLops-Aziz/mlops/lib/python3.12/site-packages/box/box.py", line 552, in __getattr__
    raise BoxKeyError(str(err)) from _exception_cause(err)
box.exceptions.BoxKeyError: "'ConfigBox' object has no attribute 'COLUMNS'"

During handling of the above exception, another exception occurred:

Traceback (most recent call last):
  File "/Users/azizkanch/mlops_learn/MLops-Aziz/mlops/lib/python3.12/site-packages/box/box.py", line 503, in __getitem__
    return super().__getitem__(item)
           ^^^^^^^^^^^^^^^^^^^^^^^^^
KeyError: 'columns'

The above exception was the direct cause of the following exception:

Traceback (most recent call last):
  File "/Users/azizkanch/mlops_learn/MLops-Aziz/mlops/lib/python3.12/site-packages/box/box.py", line 536, in __getattr__
    value = self.__getitem__(item, _ignore_default=True)
            ^^^^^^^^^^^^^^^^^^^^^^^^^^^^^^^^^^^^^^^^^^^^
  File "/Users/azizkanch/mlops_learn/MLops-Aziz/mlops/lib/python3.12/site-packages/box/box.py", line 524, in __getitem__
    raise BoxKeyError(str(err)) from _exception_cause(err)
box.exceptions.BoxKeyError: "'columns'"

During handling of the above exception, another exception occurred:

Traceback (most recent call last):
  File "/Users/azizkanch/mlops_learn/MLops-Aziz/mlops/lib/python3.12/site-packages/box/box.py", line 538, in __getattr__
    value = object.__getattribute__(self, item)
            ^^^^^^^^^^^^^^^^^^^^^^^^^^^^^^^^^^^
AttributeError: 'ConfigBox' object has no attribute 'columns'

The above exception was the direct cause of the following exception:

Traceback (most recent call last):
  File "/Users/azizkanch/mlops_learn/MLops-Aziz/main.py", line 9, in <module>
    obj.main()
  File "/Users/azizkanch/mlops_learn/MLops-Aziz/src/mlProject/pipeline/stage_02_validation.py", line 12, in main
    data_validation_config = config.get_data_validation_config()
                             ^^^^^^^^^^^^^^^^^^^^^^^^^^^^^^^^^^^
  File "/Users/azizkanch/mlops_learn/MLops-Aziz/src/mlProject/config/configuration.py", line 34, in get_data_validation_config
    schema = self.schema.COLUMNS
             ^^^^^^^^^^^^^^^^^^^
  File "/Users/azizkanch/mlops_learn/MLops-Aziz/mlops/lib/python3.12/site-packages/box/config_box.py", line 30, in __getattr__
    return super().__getattr__(item.lower())
           ^^^^^^^^^^^^^^^^^^^^^^^^^^^^^^^^^
  File "/Users/azizkanch/mlops_learn/MLops-Aziz/mlops/lib/python3.12/site-packages/box/box.py", line 552, in __getattr__
    raise BoxKeyError(str(err)) from _exception_cause(err)
box.exceptions.BoxKeyError: "'ConfigBox' object has no attribute 'columns'"
[2025-04-11 17:21:26,414: INFO: main: >>>>>> stage Data Validation Stage started <<<<<<]
[2025-04-11 17:21:26,415: INFO: common: yaml file: config/config.yaml loaded successfully]
[2025-04-11 17:21:26,415: INFO: common: yaml file: params.yaml loaded successfully]
[2025-04-11 17:21:26,416: INFO: common: yaml file: schema.yaml loaded successfully]
[2025-04-11 17:21:26,416: INFO: common: created directory at: artifacts]
[2025-04-11 17:21:26,416: INFO: common: created directory at: artifacts/data_validation]
[2025-04-11 17:21:26,416: ERROR: main: 'DataValidationConfig' object has no attribute 'validate_all_columns']
Traceback (most recent call last):
  File "/Users/azizkanch/mlops_learn/MLops-Aziz/main.py", line 9, in <module>
    obj.main()
  File "/Users/azizkanch/mlops_learn/MLops-Aziz/src/mlProject/pipeline/stage_02_validation.py", line 13, in main
    result = data_validation_config.validate_all_columns()
             ^^^^^^^^^^^^^^^^^^^^^^^^^^^^^^^^^^^^^^^^^^^
AttributeError: 'DataValidationConfig' object has no attribute 'validate_all_columns'
[2025-04-11 17:25:06,024: INFO: main: >>>>>> stage Data Validation Stage started <<<<<<]
[2025-04-11 17:25:06,025: INFO: common: yaml file: config/config.yaml loaded successfully]
[2025-04-11 17:25:06,025: INFO: common: yaml file: params.yaml loaded successfully]
[2025-04-11 17:25:06,026: INFO: common: yaml file: schema.yaml loaded successfully]
[2025-04-11 17:25:06,026: INFO: common: created directory at: artifacts]
[2025-04-11 17:25:06,026: INFO: common: created directory at: artifacts/data_validation]
[2025-04-11 17:25:06,026: ERROR: main: [Errno 2] No such file or directory: 'artifacts/data_ingestion/winequality-red.csv']
Traceback (most recent call last):
  File "/Users/azizkanch/mlops_learn/MLops-Aziz/main.py", line 9, in <module>
    obj.main()
  File "/Users/azizkanch/mlops_learn/MLops-Aziz/src/mlProject/pipeline/stage_02_validation.py", line 15, in main
    result = validation_class.validate_all_columns()
             ^^^^^^^^^^^^^^^^^^^^^^^^^^^^^^^^^^^^^^^
  File "/Users/azizkanch/mlops_learn/MLops-Aziz/src/mlProject/components/data_validation.py", line 32, in validate_all_columns
    raise e
  File "/Users/azizkanch/mlops_learn/MLops-Aziz/src/mlProject/components/data_validation.py", line 13, in validate_all_columns
    data = pd.read_csv(self.config.unzip_data_dir)
           ^^^^^^^^^^^^^^^^^^^^^^^^^^^^^^^^^^^^^^^
  File "/Users/azizkanch/mlops_learn/MLops-Aziz/mlops/lib/python3.12/site-packages/pandas/io/parsers/readers.py", line 1026, in read_csv
    return _read(filepath_or_buffer, kwds)
           ^^^^^^^^^^^^^^^^^^^^^^^^^^^^^^^
  File "/Users/azizkanch/mlops_learn/MLops-Aziz/mlops/lib/python3.12/site-packages/pandas/io/parsers/readers.py", line 620, in _read
    parser = TextFileReader(filepath_or_buffer, **kwds)
             ^^^^^^^^^^^^^^^^^^^^^^^^^^^^^^^^^^^^^^^^^^
  File "/Users/azizkanch/mlops_learn/MLops-Aziz/mlops/lib/python3.12/site-packages/pandas/io/parsers/readers.py", line 1620, in __init__
    self._engine = self._make_engine(f, self.engine)
                   ^^^^^^^^^^^^^^^^^^^^^^^^^^^^^^^^^
  File "/Users/azizkanch/mlops_learn/MLops-Aziz/mlops/lib/python3.12/site-packages/pandas/io/parsers/readers.py", line 1880, in _make_engine
    self.handles = get_handle(
                   ^^^^^^^^^^^
  File "/Users/azizkanch/mlops_learn/MLops-Aziz/mlops/lib/python3.12/site-packages/pandas/io/common.py", line 873, in get_handle
    handle = open(
             ^^^^^
FileNotFoundError: [Errno 2] No such file or directory: 'artifacts/data_ingestion/winequality-red.csv'
[2025-04-11 17:25:32,273: INFO: main: >>>>>> stage Data Validation Stage started <<<<<<]
[2025-04-11 17:25:32,274: INFO: common: yaml file: config/config.yaml loaded successfully]
[2025-04-11 17:25:32,274: INFO: common: yaml file: params.yaml loaded successfully]
[2025-04-11 17:25:32,274: INFO: common: yaml file: schema.yaml loaded successfully]
[2025-04-11 17:25:32,274: INFO: common: created directory at: artifacts]
[2025-04-11 17:25:32,274: INFO: common: created directory at: artifacts/data_validation]
[2025-04-11 17:25:32,275: ERROR: main: [Errno 2] No such file or directory: 'artifacts/data_ingestion/winequality-red.csv']
Traceback (most recent call last):
  File "/Users/azizkanch/mlops_learn/MLops-Aziz/main.py", line 9, in <module>
    obj.main()
  File "/Users/azizkanch/mlops_learn/MLops-Aziz/src/mlProject/pipeline/stage_02_validation.py", line 15, in main
    result = validation_class.validate_all_columns()
             ^^^^^^^^^^^^^^^^^^^^^^^^^^^^^^^^^^^^^^^
  File "/Users/azizkanch/mlops_learn/MLops-Aziz/src/mlProject/components/data_validation.py", line 32, in validate_all_columns
    raise e
  File "/Users/azizkanch/mlops_learn/MLops-Aziz/src/mlProject/components/data_validation.py", line 13, in validate_all_columns
    data = pd.read_csv(self.config.unzip_data_dir)
           ^^^^^^^^^^^^^^^^^^^^^^^^^^^^^^^^^^^^^^^
  File "/Users/azizkanch/mlops_learn/MLops-Aziz/mlops/lib/python3.12/site-packages/pandas/io/parsers/readers.py", line 1026, in read_csv
    return _read(filepath_or_buffer, kwds)
           ^^^^^^^^^^^^^^^^^^^^^^^^^^^^^^^
  File "/Users/azizkanch/mlops_learn/MLops-Aziz/mlops/lib/python3.12/site-packages/pandas/io/parsers/readers.py", line 620, in _read
    parser = TextFileReader(filepath_or_buffer, **kwds)
             ^^^^^^^^^^^^^^^^^^^^^^^^^^^^^^^^^^^^^^^^^^
  File "/Users/azizkanch/mlops_learn/MLops-Aziz/mlops/lib/python3.12/site-packages/pandas/io/parsers/readers.py", line 1620, in __init__
    self._engine = self._make_engine(f, self.engine)
                   ^^^^^^^^^^^^^^^^^^^^^^^^^^^^^^^^^
  File "/Users/azizkanch/mlops_learn/MLops-Aziz/mlops/lib/python3.12/site-packages/pandas/io/parsers/readers.py", line 1880, in _make_engine
    self.handles = get_handle(
                   ^^^^^^^^^^^
  File "/Users/azizkanch/mlops_learn/MLops-Aziz/mlops/lib/python3.12/site-packages/pandas/io/common.py", line 873, in get_handle
    handle = open(
             ^^^^^
FileNotFoundError: [Errno 2] No such file or directory: 'artifacts/data_ingestion/winequality-red.csv'
[2025-04-11 17:28:41,530: INFO: main: >>>>>> stage Data Ingestion Stage started <<<<<<]
[2025-04-11 17:28:41,531: INFO: common: yaml file: config/config.yaml loaded successfully]
[2025-04-11 17:28:41,531: INFO: common: yaml file: params.yaml loaded successfully]
[2025-04-11 17:28:41,531: INFO: common: yaml file: schema.yaml loaded successfully]
[2025-04-11 17:28:41,531: INFO: common: created directory at: artifacts]
[2025-04-11 17:28:41,532: INFO: common: created directory at: artifacts/data_ingestion]
[2025-04-11 17:28:42,478: INFO: data_ingestion: artifacts/data_ingestion/data.zip download! with following info: 
Connection: close
Content-Length: 23329
Cache-Control: max-age=300
Content-Security-Policy: default-src 'none'; style-src 'unsafe-inline'; sandbox
Content-Type: application/zip
ETag: "c69888a4ae59bc5a893392785a938ccd4937981c06ba8a9d6a21aa52b4ab5b6e"
Strict-Transport-Security: max-age=31536000
X-Content-Type-Options: nosniff
X-Frame-Options: deny
X-XSS-Protection: 1; mode=block
X-GitHub-Request-Id: 5AB0:30492A:1E0D42A:1F3982C:67F8FB6E
Accept-Ranges: bytes
Date: Fri, 11 Apr 2025 11:58:42 GMT
Via: 1.1 varnish
X-Served-By: cache-bom4731-BOM
X-Cache: HIT
X-Cache-Hits: 0
X-Timer: S1744372722.212914,VS0,VE270
Vary: Authorization,Accept-Encoding,Origin
Access-Control-Allow-Origin: *
Cross-Origin-Resource-Policy: cross-origin
X-Fastly-Request-ID: 5bb7b056ba51d7caeb7be1d2129ebb471fa68921
Expires: Fri, 11 Apr 2025 12:03:42 GMT
Source-Age: 0

]
[2025-04-11 17:28:42,481: INFO: main: >>>>>> stage Data Ingestion Stage completed <<<<<<

x==========x]
[2025-04-11 17:29:31,458: INFO: main: >>>>>> stage Data Ingestion Stage started <<<<<<]
[2025-04-11 17:29:31,458: INFO: common: yaml file: config/config.yaml loaded successfully]
[2025-04-11 17:29:31,458: INFO: common: yaml file: params.yaml loaded successfully]
[2025-04-11 17:29:31,459: INFO: common: yaml file: schema.yaml loaded successfully]
[2025-04-11 17:29:31,459: INFO: common: created directory at: artifacts]
[2025-04-11 17:29:31,459: INFO: common: created directory at: artifacts/data_validation]
[2025-04-11 17:29:31,463: INFO: stage_02_validation: Schema validation succeeded!]
[2025-04-11 17:29:31,463: INFO: main: >>>>>> stage Data Ingestion Stage completed <<<<<<

x==========x]
[2025-04-11 17:44:32,893: INFO: main: >>>>>> stage Data Ingestion Stage started <<<<<<]
[2025-04-11 17:44:32,896: INFO: common: yaml file: config/config.yaml loaded successfully]
[2025-04-11 17:44:32,897: INFO: common: yaml file: params.yaml loaded successfully]
[2025-04-11 17:44:32,898: INFO: common: yaml file: schema.yaml loaded successfully]
[2025-04-11 17:44:32,898: INFO: common: created directory at: artifacts]
[2025-04-11 17:44:32,898: INFO: common: created directory at: artifacts/data_validation]
[2025-04-11 17:44:32,903: INFO: stage_02_validation: Schema validation succeeded!]
[2025-04-11 17:44:32,903: INFO: main: >>>>>> stage Data Ingestion Stage completed <<<<<<

x==========x]
[2025-04-12 09:53:24,408: INFO: main: >>>>>> stage Data Ingestion Stage started <<<<<<]
[2025-04-12 09:53:24,409: INFO: common: yaml file: config/config.yaml loaded successfully]
[2025-04-12 09:53:24,409: INFO: common: yaml file: params.yaml loaded successfully]
[2025-04-12 09:53:24,410: INFO: common: yaml file: schema.yaml loaded successfully]
[2025-04-12 09:53:24,410: INFO: common: created directory at: artifacts]
[2025-04-12 09:53:24,410: INFO: common: created directory at: artifacts/data_ingestion]
[2025-04-12 09:53:24,410: INFO: data_ingestion: File already exists of size: ~ 23 KB]
[2025-04-12 09:53:24,411: INFO: main: >>>>>> stage Data Ingestion Stage completed <<<<<<

x==========x]
[2025-04-12 09:53:24,411: INFO: main: >>>>>> stage Data Validation Stage started <<<<<<]
[2025-04-12 09:53:24,412: INFO: common: yaml file: config/config.yaml loaded successfully]
[2025-04-12 09:53:24,412: INFO: common: yaml file: params.yaml loaded successfully]
[2025-04-12 09:53:24,413: INFO: common: yaml file: schema.yaml loaded successfully]
[2025-04-12 09:53:24,413: INFO: common: created directory at: artifacts]
[2025-04-12 09:53:24,413: INFO: common: created directory at: artifacts/data_validation]
[2025-04-12 09:53:24,417: INFO: stage_02_validation: Schema validation succeeded!]
[2025-04-12 09:53:24,417: INFO: main: >>>>>> stage Data Validation Stage completed <<<<<<

x==========x]
